Workbook

Sheet Original
A1: actor | B1: Umbrella_name_1 | C1: Umbrella_name_2 | D1: Umbrella_name_3 | E1: Umbrella_id_1 | F1: Umbrella_id_2 | G1: Umbrella_id_3 | H1: match_grade | I1: Source | J1: Notes | N1: Type | P1: Allies
A2: 13th Division | B2: Free Syrian Army | E2: 6 | H2: A | I2: https://www.reuters.com/article/us-mideast-crisis-syria-idlib/air-strike-on-market-kills-around-40-in-opposition-held-northwest-syria-idUSKCN0XG1XT | J2: Lines up with ACLED battle descriptions. Wikipedia link: https://en.wikipedia.org/wiki/13th_Division_(Syrian_rebel_group) | L2: Al Qaeda | M2: 1
A3: 1st Brigade of Damascus | B3: Free Syrian Army | E3: 6 | H3: A | I3: http://www.orient-news.net/en/news_show/110355/Oppositions-First-Brigade-merges-into-al-Rahman-Brigade-in-Damascus- | J3: Merged into al-Rahman Brigades, which are part of FSA. Source: http://www.dw.com/en/which-rebel-groups-are-fighting-in-syrias-eastern-ghouta/a-42663501 | L3: Jaysh al-Fatah | M3: 2 | N3: Sunni Islamist | P3: Free Syrian Army
A4: 1st Coastal Division | B4: Free Syrian Army | E4: 6 | H4: A | I4: http://www.rubincenter.org/2015/12/the-factions-of-north-latakia/ | L4: Al-Fawj Al-Awl | M4: 3 | N4: Sunni Islamist | P4: Free Syrian Army
A5: 1st Regiment | B5: The Southern Front | E5: 12 | H5: A | I5: https://notgeorgesabra.wordpress.com/2014/10/21/the-moderate-rebels-a-complete-and-growing-list-of-vetted-groups/ | J5: aka 1st Artillery Regiment | L5: The Levantine Front | M5: 4 | N5: Sunni Islamist | P5: Free Syrian Army
A6: 3rd Corps | B6: Free Syrian Army | E6: 6 | H6: A | I6: https://syria.liveuamap.com/en/2018/20-february-afrinop-3rd-corps-of-national-army-storming-with | J6: Note that in the description of events that include 3rd corps, it is listed as an FSA group fighting against YPG | L6: Jaysh al-Islam | M6: 5 | N6: Sunni Islamist | P6: Free Syrian Army
A7: 9th Division Special Forces | B7: Free Syrian Army | E7: 6 | H7: A | I7: https://smartnews-agency.com/en/media/249654/the-9th-division--graduates-a-military-class-in-jarablus | L7: Free Syrian Army | M7: 6 | N7: Sunni Islamist | P7: Free Syrian Army
A8: AAS: Ahrar al-Sham | B8: Ahrar al-Sham | E8: 20 | H8: A | I8: Definition | J8: One of largest Sunni Islamist groups, maybe should be an umbrella organization. Recently merged with Nour al-Din al-Zenki to form Syrian Liberation Force (!). Wikipedia link: https://en.wikipedia.org/wiki/Ahrar_al-Sham | L8: Faylaq al-Rahman | M8: 7 | N8: Sunni Islamist | P8: Free Syrian Army
A9: AJA: Ahrar Jabal Al-Sheikh | H9: C | J9: No exact link to any umbrella organization. Group seems to fight against government forces in alliance with FSA, HTS | L9: Ajnad al-Sham Islamic Union | M9: 8 | P9: Jaysh al-Islam
A10: Abu Amara Brigade | B10: The Levantine Front | E10: 4 | H10: C | I10: Wikipedia *** DOUBLE-CHECK ***
A11: Abna al-Sham (Hama) | B11: Free Syrian Army | E11: 6 | H11: A | I11: https://www.longwarjournal.org/archives/2017/03/analysis-insurgents-launch-major-offensive-against-assad-regime-in-hama-province.php | L11: Popular Mobilization Forces | M11: 9 | N11: Shia | P11: Iraq | Q11: Iran
A12: Ahmad al-Abdo Forces | B12: The Southern Front | E12: 12 | H12: A | I12: https://www.newsdeeply.com/syria/community/2017/03/01/fmaa-our-priority-is-to-establish-our-free-future-state | L12: Hezbollah | M12: 10 | N12: Shia | P12: Iran
A13: Ahrar Al Sharqiyah | B13: Free Syrian Army | E13: 6 | H13: A | I13: https://www.almasdarnews.com/article/syrian-army-neutralizes-turkish-backed-troops-near-al-bab/ | J13: This is a duplicate with slightly different spelling. Seems like some within this group have defected to SDF, per this article: http://theregion.org/article/12722-disillusioned-jihadist-ahrar-al-sharqiya-members-defect-to-sdf-backed-council | L13: Syrian Democratic Forces | M13: 11 | N13: Kurdish | P13: USA | Q13: Russia
A14: Ahrar Nawa Brigade | B14: The Southern Front | E14: 12 | H14: A | I14: https://rfsmediaoffice.com/en/2017/02/14/coalition-southern-forces/ | L14: The Southern Front | M14: 12 | N14: Secular | P14: USA
A15: Ahrar al-Sharqiyah | B15: Free Syrian Army | E15: 6 | H15: A | I15: https://www.almasdarnews.com/article/syrian-army-neutralizes-turkish-backed-troops-near-al-bab/ | J15: This is a duplicate with slightly different spelling. Seems like some within this group have defected to SDF, per this article: http://theregion.org/article/12722-disillusioned-jihadist-ahrar-al-sharqiya-members-defect-to-sdf-backed-council | L15: Islamic State | M15: 13
A16: Ajnad al-Sham Islamic Union | B16: Ajnad al-Sham Islamic Union | E16: 8 | H16: A | I16: Definition | L16: Military Forces of Syria | M16: 14
A17: Aknaf Bait al-Maqdis | H17: C | I17: http://www.syriahr.com/en/?p=77014 | J17: Appear in ACLED as fighting alongside Sham al-Rasoul Brigade against the Islamic State, but no clear umbrella organization | L17: Russia | M17: 15
A18: Aknaf Bayt al-Maqdes | H18: C | I18: http://www.syriahr.com/en/?p=77014 | J18: Appear in ACLED as fighting alongside Sham al-Rasoul Brigade against the Islamic State, but no clear umbrella organization. Note there is a duplicate entry that spells Bayt as "Bait" and Maqdes as "Maqdis" | L18: Iran | M18: 16
A19: Al Haramain Brigades | B19: Syrian Democratic Forces | E19: 11 | H19: A | I19: https://twitter.com/QSD00963/status/707950225260937216 | J19: Name does not match exactly. The following link in German, confirmed with Google Translate, is reputable source: http://www.kurdistan-report.de/index.php/archiv/2017/54-kr-193-september-oktober-2017/623-die-qsd-eine-kampfgruppe-der-gesellschaften-syriens | L19: Turkey | M19: 17
A20: Al Qaeda | B20: Al Qaeda | E20: 1 | H20: A | I20: Definition | L20: USA | M20: 18
A21: Al Sham Corps | H21: C | I21: https://www.reuters.com/article/us-mideast-crisis-syria-rebels/syrian-rebel-group-says-exits-islamist-alliance-to-refocus-fight-idUSKBN0UH08Q20160103?feedType=RSS&feedName=worldNews | J21: Duplicate | L21: Israel | M21: 19
A22: Al-Haramain Brigade | B22: Syrian Democratic Forces | E22: 11 | H22: A | I22: https://twitter.com/QSD00963/status/707950225260937216 | J22: Name does not match exactly. The following link in German, confirmed with Google Translate, is reputable source: http://www.kurdistan-report.de/index.php/archiv/2017/54-kr-193-september-oktober-2017/623-die-qsd-eine-kampfgruppe-der-gesellschaften-syriens | L22: Ahrar al-Sham | M22: 20 | N22: Sunni Islamist | P22: Free Syrian Army
A23: Al-Muwali Brigade (Syria) | B23: Free Syrian Army | E23: 6 | H23: A | I23: https://www.hate-speech.org/tribes-of-syria-pieces-on-a-chessboard/ | J23: Slightly different spelling on the source link, "malawi", but lines up with other sources reviewed.
A24: Al-Safirah Brigade | B24: Military Forces of Syria | E24: 14 | H24: A | I24: http://www.aymennjawad.org/18859/the-local-defence-forces-regime-auxiliary-forces | J24: Name does not match exactly: "Safira Regiment" vs. "al-Safira Brigade"
A25: Al-Sham Corps | H25: C | I25: https://www.reuters.com/article/us-mideast-crisis-syria-rebels/syrian-rebel-group-says-exits-islamist-alliance-to-refocus-fight-idUSKBN0UH08Q20160103?feedType=RSS&feedName=worldNews | J25: Group withdrew from Jaysh al-Fatah in 2016, reasserting its independence. Al Sham Corps = Sham Legion = Faylaq al-Sham. But it is unclear which umbrella group it belongs to.
A26: Al-Tawhid Army | H26: C | J26: Does not fit into any of the umbrella organizations
A27: Al-Wosta Division | B27: Free Syrian Army | E27: 6 | H27: A | I27: http://en.farsnews.com/newstext.aspx?nn=13960418000232
A28: Allied Syrian and/or Russian Forces | B28: Military Forces of Syria | E28: 14 | H28: B | J28: Could be Syrian military or Russia (id = 15)
A29: Ansar al-Islam | H29: C | I29: http://web.stanford.edu/group/mappingmilitants/cgi-bin/groups/view/13 | J29: Ansar al-Islam was a Sunni group that spanned Iraq and Syria from 2001 to 2014. In 2013-2014, the group clashed with the Islamic State (IS), because it considered IS’s claiming itself as the caliphate premature and undeserved. However, on August 2014, Iraqi leaders of Ansar al-Islam declared that they would be joining IS, so that 90% or more of Iraqi Ansar al-Islam joined IS. Ansar al-Islam in Iraq thus effectively disbanded, while the Syria branch rejected the declaration and remains an independent organization, still fights IS. Only remnants are left in Syria.
A30: Arab Nationalist Guard | B30: Military Forces of Syria | E30: 14 | H30: A | I30: http://www.aymennjawad.org/14235/arab-nationalist-guard
A31: Army of Mujahideen | B31: Mujahideen Army | E31: 6 | H31: A | I31: https://syriainbrief.wordpress.com/2018/01/02/the-cias-tow-program-a-list-of-rebel-groups-involved/ | J31: Note that the group has now disbanded and integrated into Ahrar ash-Sham
A32: As-Sweida Communal Militia (Syria) | H32: C | J32: This group has seemingly rejected FSA alliance offerings, but it is unclear whether or not it is allied with government. Source: https://www.almasdarnews.com/article/druze-of-as-sweida-reject-fsa-peace-offering/
A33: Asayish (Syria) | B33: Syrian Democratic Forces | E33: 11 | H33: B | I33: http://www.middleeasteye.net/news/anti-coalition-trains-policemen-syrias-raqqa-1227633581 | J33: The group is for the most part a Kurdish police force in Northern Syria (Rojava), but it has also had involvement with military campaigns. Seems like more recently, the force has become more integrated with the SDF (from source cited)
A34: Ba'ath Party Members (Syria) | B34: Military Forces of Syria | E34: 14 | H34: B | I34: https://en.wikipedia.org/wiki/Ba%27ath_Party_(Syrian-dominated_faction) | J34: Ba'ath Party is aligned with the government (has been ruling party in Syria for half a century), so it would be aligned with Military Forces of Syria, but the match is not exact.
A35: Bakkara Youth Gathering (Syria) | B35: Syrian Democratic Forces | E35: 11 | H35: A | I35: http://www.syriahr.com/en/?p=73900 | J35: DUPLICATE - Same as "al-Bakkara Youth Gathering (Syria) (Syria)" above
A36: Banyan al-Marsus | B36: Free Syrian Army | E36: 6 | H36: A | I36: http://www.atlanticcouncil.org/blogs/syriasource/the-battle-for-deraa-and-iran-s-plans-in-the-south
A37: Civilians | H37: C | J37: Vague description
A38: Eagles of the Whirlwind | B38: Military Forces of Syria | E38: 14 | H38: C | I38: Wikipedia *** DOUBLE-CHECK ***
A39: Eastern Shield Army | B39: Free Syrian Army | E39: 6 | H39: A | I39: https://southfront.org/militants-announced-formation-of-eastern-shield-army/
A40: FFaI: Dawn of Islam Division | B40: Free Syrian Army | E40: 6 | H40: A | I40: https://twitter.com/rufus_mcdonald/status/839283019227639808 | J40: No concrete reliable source, but all of them point to FSA (possibly Southern Front) affiliation
...

Sheet Merging2_New
B1: Actor | C1: Counts | D1: Umbrella | E1: Comment
A2: 0 | B2: Military Forces of Syria | C2: 29028 | D2: Military Forces of Syria
A3: 1 | B3: Syrian Democratic Forces | C3: 8988 | D3: Syrian Democratic Forces
A4: 2 | B4: Islamic State in Iraq and the Levant (ISIL) | C4: 7934 | D4: The Islamic State
A5: 3 | B5: Opposition Rebels (Syria) | C5: 6823
A6: 4 | B6: Unidentified Armed Group (Syria) | C6: 4823
A7: 5 | B7: HTS: Hayat Tahrir al Sham | C7: 3052 | D7: HTS: Hayat Tahrir al-Sham
A8: 6 | B8: Military Forces of Turkey (2016-) | C8: 1276 | D8: Turkey
A9: 7 | B9: Free Syrian Army | C9: 1244 | D9: Free Syrian Army
A10: 8 | B10: Global Coalition Against Daesh | C10: 1232
A11: 9 | B11: Military Forces of Russia (2000-) | C11: 1125 | D11: Russia
A12: 10 | B12: Operation Peace Spring | C12: 860 | D12: Turkey
A13: 11 | B13: AAS: Ahrar al Sham | C13: 682 | D13: Ahrar al-Sham
A14: 12 | B14: QDW: National Defence Forces | C14: 577 | D14: Military Forces of Syria
A15: 13 | B15: Turkey | C15: 575 | D15: Turkey
A16: 14 | B16: Al Fath Al Mubeen Operation Room | C16: 574 | D16: HTS: Hayat Tahrir al-Sham
A17: 15 | B17: Tribal and Clan Forces | C17: 546
A18: 16 | B18: Hezbollah | C18: 529 | D18: Hezbollah
A19: 17 | B19: FaR: Al Rahman Corps | C19: 507 | D19: Faylaq al-Rahman
A20: 18 | B20: Former Opposition Rebels (Syria) | C20: 427
A21: 19 | B21: Jaysh al Islam | C21: 388 | D21: Jaysh al-Islam
A22: 20 | B22: Militia (Pro-Iran) | C22: 371 | D22: Iran
A23: 21 | B23: Khalid ibn al Walid Army | C23: 343 | D23: Khalid ibn al Walid Army
A24: 22 | B24: JTW: National Liberation Front | C24: 328 | D24: Free Syrian Army
A25: 23 | B25: National Police Forces | C25: 234 | D25: Military Forces of Syria
A26: 24 | B26: Military Forces of the United States (2017-2021) | C26: 226 | D26: USA
A27: 25 | B27: HNDZ: Nour al Din al Zinki Movement | C27: 211 | D27: Harakat Nour al-Din al-Zenki
A28: 26 | B28: Military Forces of the United States (2017-2021) Special Forces | C28: 209 | D28: USA
A29: 27 | B29: Military Operations Command | C29: 207
A30: 28 | B30: The Levantine Front | C30: 201 | D30: The Levantine Front
A31: 29 | B31: Al Qaeda | C31: 196 | D31: Al Qaeda
A32: 30 | B32: Al Sham Corps | C32: 185 | D32: HTS: Hayat Tahrir al-Sham
A33: 31 | B33: Iran | C33: 185 | D33: Iran
A34: 32 | B34: Suquor al Sham | C34: 166 | D34: Ahrar al-Sham
A35: 33 | B35: Military Forces of Iran (1989-) Islamic Revolutionary Guard Corps | C35: 165 | D35: Iran
A36: 34 | B36: HXP: Self-Defence Forces | C36: 157 | D36: Syrian Democratic Forces
A37: 35 | B37: The Southern Front | C37: 156 | D37: The Southern Front
A38: 36 | B38: Ahrar al Sharqiyah | C38: 152 | D38: Free Syrian Army
A39: 37 | B39: MDA: Deir-ez-Zor Military Council | C39: 149 | D39: Syrian Democratic Forces
A40: 38 | B40: Jabhat Fateh al Sham | C40: 119
...

Sheet Merging2
A1: Actor | B1: Count | C1: Umbrella
A2: Military Forces of Syria | B2: 28270 | C2: Military Forces of Syria
A3: Syrian Democratic Forces | B3: 8331 | C3: Syrian Democratic Forces
A4: Islamic State | B4: 7712 | C4: The Islamic State
A5: Opposition Rebels (Syria) | B5: 6735 | C5: x
A6: Unidentified Armed Group (Syria) | B6: 4676 | C6: x
A7: HTS: Hayat Tahrir al Sham | B7: 3018 | C7: HTS: Hayat Tahrir al-Sham
A8: Global Coalition Against Daesh | B8: 1205 | C8: x
A9: Free Syrian Army | B9: 1201 | C9: Free Syrian Army
A10: Military Forces of Turkey (2016-) | B10: 1176 | C10: Turkey
A11: Military Forces of Russia (2000-) | B11: 1097 | C11: Russia
A12: Operation Peace Spring | B12: 831 | C12: Turkey
A13: AAS: Ahrar al Sham | B13: 679 | C13: Ahrar al-Sham
... A83: Hajin Military Council | B83: 20 | C83: Syrian Democratic Forces
A84: 20th Division | B84: 19
A85: Free Syrian Police | B85: 18
A86: Al Shahba Assembly | B86: 17
A87: Military Forces of Turkey (2016-) Gendarmerie | B87: 17 | C87: Turkey
A88: Ajnad al Sham Islamic Union | B88: 16
A89: Quneitra Hawks | B89: 16 | C89: x
A90: Harakat Hezbollah Al Nujaba | B90: 16 | C90: x
A91: Northern Hawks Brigade | B91: 15 | C91: x
A92: Liwa Fajr al Umma | B92: 15 | C92: x
A93: Shuhada Badr | B93: 15
A94: Military Forces of Jordan (1999-) | B94: 15 | C94: x
A95: Liwa al Baqir | B95: 15 | C95: x
A96: Islamist Militia (International) | B96: 14 | C96: x
A97: QSF: Qalamoon Shield Forces | B97: 14
A98: Syriac Military Council (Syria) | B98: 14
A99: Abu Bakr as-Siddiq Army | B99: 14 | C99: x
A100: Ajnad al Sham | B100: 13
A101: Private Security Forces (Syria) | B101: 13
A102: YPG: Peoples Protection Units - Hezen Komandoz | B102: 12
A103: Syriac Security Office (Syria) | B103: 12 | C103: Military Forces of Syria
A104: Military Forces of Iran (1989-) Quds Force | B104: 12 | C104: Iran
A105: Military Forces of Iraq (2020-2022) Popular Mobilization Forces | B105: 12 | C105: Popular Mobilization Forces
A106: Sheikh al-Karama | B106: 12 | C106: x
A107: Former Mutaaz Billah Army | B107: 11
A108: Military Forces of Iraq (2014-2018) Popular Mobilization Forces | B108: 11 | C108: Popular Mobilization Forces
A109: Ahrar Jabal al Sheikh | B109: 11
...

Sheet Merging2_backup
A1: Actor | B1: Counts | C1: Matching | D1: Umbrella
A2: Military Forces of Syria | B2: 29028 | C2: =_xlfn.XLOOKUP(A2,Merging2!A:A,Merging2!C:C," ",) -> Military Forces of Syria | D2: =IF(C2<>0,C2,"") -> Military Forces of Syria
A3: Syrian Democratic Forces | B3: 8988 | C3: =_xlfn.XLOOKUP(A3,Merging2!A:A,Merging2!C:C," ",) -> Syrian Democratic Forces | D3: =IF(C3<>0,C3,"") -> Syrian Democratic Forces
A4: Islamic State in Iraq and the Levant (ISIL) | B4: 7934 | C4: The Islamic State | D4: =IF(C4<>0,C4,"") -> The Islamic State
A5: Opposition Rebels (Syria) | B5: 6823 | C5: =_xlfn.XLOOKUP(A5,Merging2!A:A,Merging2!C:C," ",) -> x | D5: =IF(C5<>0,C5,"") -> x
A6: Unidentified Armed Group (Syria) | B6: 4823 | C6: =_xlfn.XLOOKUP(A6,Merging2!A:A,Merging2!C:C," ",) -> x | D6: =IF(C6<>0,C6,"") -> x
A7: HTS: Hayat Tahrir al Sham | B7: 3052 | C7: =_xlfn.XLOOKUP(A7,Merging2!A:A,Merging2!C:C," ",) -> HTS: Hayat Tahrir al-Sham | D7: =IF(C7<>0,C7,"") -> HTS: Hayat Tahrir al-Sham
A8: Military Forces of Turkey (2016-) | B8: 1276 | C8: =_xlfn.XLOOKUP(A8,Merging2!A:A,Merging2!C:C," ",) -> Turkey | D8: =IF(C8<>0,C8,"") -> Turkey
A9: Free Syrian Army | B9: 1244 | C9: =_xlfn.XLOOKUP(A9,Merging2!A:A,Merging2!C:C," ",) -> Free Syrian Army | D9: =IF(C9<>0,C9,"") -> Free Syrian Army
A10: Global Coalition Against Daesh | B10: 1232 | C10: =_xlfn.XLOOKUP(A10,Merging2!A:A,Merging2!C:C," ",) -> x | D10: =IF(C10<>0,C10,"") -> x
A11: Military Forces of Russia (2000-) | B11: 1125 | C11: =_xlfn.XLOOKUP(A11,Merging2!A:A,Merging2!C:C," ",) -> Russia | D11: =IF(C11<>0,C11,"") -> Russia
A12: Operation Peace Spring | B12: 860 | C12: =_xlfn.XLOOKUP(A12,Merging2!A:A,Merging2!C:C," ",) -> Turkey | D12: =IF(C12<>0,C12,"") -> Turkey
A13: AAS: Ahrar al Sham | B13: 682 | C13: =_xlfn.XLOOKUP(A13,Merging2!A:A,Merging2!C:C," ",) -> Ahrar al-Sham | D13: =IF(C13<>0,C13,"") -> Ahrar al-Sham
A14: QDW: National Defence Forces | B14: 577 | C14: =_xlfn.XLOOKUP(A14,Merging2!A:A,Merging2!C:C," ",) -> Military Forces of Syria | D14: =IF(C14<>0,C14,"") -> Military Forces of Syria
A15: Turkey | B15: 575 | C15: =_xlfn.XLOOKUP(A15,Merging2!A:A,Merging2!C:C," ",) -> Turkey | D15: =IF(C15<>0,C15,"") -> Turkey
A16: Al Fath Al Mubeen Operation Room | B16: 574 | C16: =_xlfn.XLOOKUP(A16,Merging2!A:A,Merging2!C:C," ",) -> HTS: Hayat Tahrir al-Sham | D16: =IF(C16<>0,C16,"") -> HTS: Hayat Tahrir al-Sham
... A28: Military Forces of the United States (2017-2021) Special Forces | B28: 209 | C28: =_xlfn.XLOOKUP(A28,Merging2!A:A,Merging2!C:C," ",) -> USA | D28: =IF(C28<>0,C28,"") -> USA
A29: Military Operations Command | B29: 207 | C29: x | D29: =IF(C29<>0,C29,"") -> x
A30: The Levantine Front | B30: 201 | C30: =_xlfn.XLOOKUP(A30,Merging2!A:A,Merging2!C:C," ",) -> The Levantine Front | D30: =IF(C30<>0,C30,"") -> The Levantine Front
A31: Al Qaeda | B31: 196 | C31: =_xlfn.XLOOKUP(A31,Merging2!A:A,Merging2!C:C," ",) -> Al Qaeda | D31: =IF(C31<>0,C31,"") -> Al Qaeda
A32: Al Sham Corps | B32: 185 | C32: =_xlfn.XLOOKUP(A32,Merging2!A:A,Merging2!C:C," ",) -> HTS: Hayat Tahrir al-Sham | D32: =IF(C32<>0,C32,"") -> HTS: Hayat Tahrir al-Sham
A33: Iran | B33: 185 | C33: =_xlfn.XLOOKUP(A33,Merging2!A:A,Merging2!C:C," ",) -> Iran | D33: =IF(C33<>0,C33,"") -> Iran
A34: Suquor al Sham | B34: 166 | C34: =_xlfn.XLOOKUP(A34,Merging2!A:A,Merging2!C:C," ",) -> Ahrar al-Sham | D34: =IF(C34<>0,C34,"") -> Ahrar al-Sham
A35: Military Forces of Iran (1989-) Islamic Revolutionary Guard Corps | B35: 165 | C35: =_xlfn.XLOOKUP(A35,Merging2!A:A,Merging2!C:C," ",) -> Iran | D35: =IF(C35<>0,C35,"") -> Iran
A36: HXP: Self-Defence Forces | B36: 157 | C36: =_xlfn.XLOOKUP(A36,Merging2!A:A,Merging2!C:C," ",) -> Syrian Democratic Forces | D36: =IF(C36<>0,C36,"") -> Syrian Democratic Forces
A37: The Southern Front | B37: 156 | C37: =_xlfn.XLOOKUP(A37,Merging2!A:A,Merging2!C:C," ",) -> The Southern Front | D37: =IF(C37<>0,C37,"") -> The Southern Front
A38: Ahrar al Sharqiyah | B38: 152 | C38: =_xlfn.XLOOKUP(A38,Merging2!A:A,Merging2!C:C," ",) -> Free Syrian Army | D38: =IF(C38<>0,C38,"") -> Free Syrian Army
A39: MDA: Deir-ez-Zor Military Council | B39: 149 | C39: =_xlfn.XLOOKUP(A39,Merging2!A:A,Merging2!C:C," ",) -> Syrian Democratic Forces | D39: =IF(C39<>0,C39,"") -> Syrian Democratic Forces
A40: Jabhat Fateh al Sham | B40: 119 | C40: =_xlfn.XLOOKUP(A40,Merging2!A:A,Merging2!C:C," ",) -> x | D40: =IF(C40<>0,C40,"") -> x
A41: Police Forces of Syria (2000-2024) | B41: 116 | C41: Military Forces of Syria | D41: =IF(C41<>0,C41,"") -> Military Forces of Syria
A42: Police Forces of Syria (2000-2024) State Security | B42: 105 | C42: Military Forces of Syria | D42: =IF(C42<>0,C42,"") -> Military Forces of Syria
A43: Military Forces of the United Kingdom (2010-2024) | B43: 94 | C43: UK | D43: =IF(C43<>0,C43,"") -> UK
A44: Jaysh al Nasr | B44: 92 | C44: =_xlfn.XLOOKUP(A44,Merging2!A:A,Merging2!C:C," ",) -> x | D44: =IF(C44<>0,C44,"") -> x
A45: Hamza Brigade | B45: 87 | C45: =_xlfn.XLOOKUP(A45,Merging2!A:A,Merging2!C:C," ",) -> Free Syrian Army | D45: =IF(C45<>0,C45,"") -> Free Syrian Army
A46: Smugglers (Syria) | B46: 84 | C46: =_xlfn.XLOOKUP(A46,Merging2!A:A,Merging2!C:C," ",) -> x | D46: =IF(C46<>0,C46,"") -> x
A47: Former Operation Euphrates Shield | B47: 84 | C47: =_xlfn.XLOOKUP(A47,Merging2!A:A,Merging2!C:C," ",) -> x | D47: =IF(C47<>0,C47,"") -> x
A48: Hurras al Deen | B48: 83 | C48: =_xlfn.XLOOKUP(A48,Merging2!A:A,Merging2!C:C," ",) -> Al Qaeda | D48: =IF(C48<>0,C48,"") -> Al Qaeda
A49: JTS: Syria Liberation Front | B49: 82 | C49: =_xlfn.XLOOKUP(A49,Merging2!A:A,Merging2!C:C," ",) -> JTS: Syria Liberation Front | D49: =IF(C49<>0,C49,"") -> JTS: Syria Liberation Front
A50: Ahmad al Abdo Forces | B50: 79 | C50: =_xlfn.XLOOKUP(A50,Merging2!A:A,Merging2!C:C," ",) -> The Southern Front | D50: =IF(C50<>0,C50,"") -> The Southern Front
A51: Islamist Rebels (Syria) | B51: 75 | C51: =_xlfn.XLOOKUP(A51,Merging2!A:A,Merging2!C:C," ",) -> x | D51: =IF(C51<>0,C51,"") -> x
...
