Workbook

Sheet Renaming
A1: Umbrella | B1: Stanford_Name | C1: Wiki_Name | D1: ACLED_Name | E1: Manual_Name
A2: Ahrar al-Sham | B2: Ahrar al-Sham | C2: Ahrar al-Sham | D2: Ahrar al-Sham | E2: aas
A3: Aknaf Bait al-Maqdis | C3: Aknaf Bait al-Maqdis | D3: Aknaf Bait al Maqdis | E3: abam
A4: Al Qaeda | B4: Al Qaeda | C4: Al-Qaeda | D4: Al Qaeda | E4: aq
A5: Authenticity and Development Front | C5: Authenticity and Development Front
A6: Faylaq al-Rahman | B6: Faylaq al-Rahman | C6: Al-Rahman Legion | D6: Faylaq al-Rahman | E6: far
A7: Free Syrian Army | B7: Free Syrian Army | C7: Free Syrian Army | D7: Free Syrian Army | E7: fsa
A8: Harakat Nour al-Din al-Zenki | B8: Harakat Nour al-Din al-Zenki | C8: Nour al-Din al-Zenki Movement | D8: Harakat Nour al-Din al-Zenki
A9: Hezbollah | B9: Hezbollah | C9: Hezbollah | D9: Hezbollah | E9: hez
A10: HTS: Hayat Tahrir al-Sham | B10: Hay'at Tahrir al-Sham (Formerly Jabhat al-Nusra) | C10: Tahrir al-Sham | D10: HTS: Hayat Tahrir al-Sham | E10: hts
A11: Iran | C11: Iran | D11: Iran | E11: ira
A12: Iraq | C12: Iraq | D12: Iraq | E12: irq
A13: Israel | C13: Israel | D13: Israel | E13: isr
A14: Jaish al-Muhajireen wal-Ansar | C14: Liwa al-Muhajireen wal-Ansar
A15: Jaysh al-Fatah | D15: Jaysh al-Fatah | E15: jaf
A16: Jaysh al-Islam | B16: Jaysh al-Islam | C16: Jaysh al-Islam | D16: Jaysh al-Islam | E16: jai
A17: Jaysh al-Sanadeed | B17: Jaysh al-Sanadeed | C17: Al-Sanadid Forces | D17: JaS: Al Sanadid Forces (Syria)
A18: JTS: Syria Liberation Front | C18: Syrian Liberation Front | D18: JTS: Syria Liberation Front
A19: Kurdish Islamic Front | B19: Kurdish Islamic Front
A20: Liwa al-Tawhid | B20: Liwa al-Tawhid | D20: Liwa al-Tawhid
A21: Military Forces of Syria | C21: Syria | D21: Military Forces of Syria | E21: mfs
A22: Mujahideen Army | B22: Jaysh al-Mujahedeen | C22: Army of Mujahideen | D22: Mujahideen Army
A23: Mujahideen Shura Council | C23: Mujahideen Shura Council
A24: Peoples Protection Units | B24: Peoples Protection Units | C24: People's Protection Units | D24: Peoples Protection Units | E24: pmf
A25: Sham Legion | C25: Sham Legion | E25: sl
A26: Suqour al-Sham | B26: Suqour al-Sham | C26: Suqour al-Sham Brigades
A27: Syrian Democratic Forces | C27: Syrian Democratic Forces | D27: Syrian Democratic Forces | E27: sdf
A28: The Islamic State | B28: The Islamic State | C28: Islamic State of Iraq and the Levant | D28: The Islamic State | E28: isis
A29: The Levantine Front | B29: The Levantine Front | C29: Levant Front | D29: The Levantine Front
A30: The Southern Front | B30: The Southern Front | C30: Southern Front | D30: The Southern Front | E30: sf
A31: Turkey | C31: Turkey | D31: Turkey | E31: tur
A32: USA | C32: United States | D32: USA | E32: usa
A33: Russia | C33: Russia | D33: Russia | E33: rus
A34: Kurdish Front | C34: Kurdish Front | D34: Al Akrad Front
A35: Global Coalition Against Daesh | D35: Global Coalition Against Daesh
A36: Operation Peace Spring | D36: Operation Peace Spring
A37: Khalid ibn al Walid Army | D37: Khalid ibn al Walid Army
A38: pre-HTS | D38: pre-HTS

Sheet all_names
A1: Name
A2: Ahrar al-Sham | B2: =_xlfn.XLOOKUP(A2,Renaming!A:A,Renaming!A:A,,) -> Ahrar al-Sham
A3: Aknaf Bait al-Maqdis | B3: =_xlfn.XLOOKUP(A3,Renaming!A:A,Renaming!A:A,,) -> Aknaf Bait al-Maqdis
A4: Al Qaeda | B4: =_xlfn.XLOOKUP(A4,Renaming!A:A,Renaming!A:A,,) -> Al Qaeda
A5: Authenticity and Development Front | B5: =_xlfn.XLOOKUP(A5,Renaming!A:A,Renaming!A:A,,) -> Authenticity and Development Front
A6: Civilians | B6: =_xlfn.XLOOKUP(A6,Renaming!A:A,Renaming!A:A,,) -> #N/A
A7: Faylaq al-Rahman | B7: =_xlfn.XLOOKUP(A7,Renaming!A:A,Renaming!A:A,,) -> Faylaq al-Rahman
A8: Free Syrian Army | B8: =_xlfn.XLOOKUP(A8,Renaming!A:A,Renaming!A:A,,) -> Free Syrian Army
A9: HTS: Hayat Tahrir al-Sham | B9: =_xlfn.XLOOKUP(A9,Renaming!A:A,Renaming!A:A,,) -> HTS: Hayat Tahrir al-Sham
A10: Harakat Nour al-Din al-Zenki | B10: =_xlfn.XLOOKUP(A10,Renaming!A:A,Renaming!A:A,,) -> Harakat Nour al-Din al-Zenki
A11: Hezbollah | B11: =_xlfn.XLOOKUP(A11,Renaming!A:A,Renaming!A:A,,) -> Hezbollah
A12: Iran | B12: =_xlfn.XLOOKUP(A12,Renaming!A:A,Renaming!A:A,,) -> Iran
A13: Iraq | B13: =_xlfn.XLOOKUP(A13,Renaming!A:A,Renaming!A:A,,) -> Iraq
... A40: x | B40: =_xlfn.XLOOKUP(A40,Renaming!A:A,Renaming!A:A,,) -> #N/A

Sheet all_names-reasoning
A1: Civilians | B1: unidentifiable
A2: Liwa al-Fateh | B2: by-product of merging with ACLED
A3: Popular Mobilization Forces | B3: by-product of merging with ACLED
A4: Syrian Insurgents | B4: unidentifiable
A5: UK | B5: by-product of merging with ACLED
A6: x | B6: unidentifiable

Sheet manual_full
A1: Primary Group | B1: Other Group | C1: Relationship | D1: allied_multi | E1: enemy_multi | F1: start | G1: end
A2: abam | B2: isis | C2: Enemy | D2: 0 | E2: 1 | F2: 2015
A3: gcad | B3: usa | C3: Ally | D3: 1 | E3: 0 | F3: x
A4: gcad | B4: jor | C4: Ally | D4: 1 | E4: 0 | F4: x
A5: gcad | B5: uk | C5: Ally | D5: 1 | E5: 0 | F5: x
A6: gcad | B6: sau | C6: Ally | D6: 1 | E6: 0 | F6: x
A7: gcad | B7: qat | C7: Ally | D7: 1 | E7: 0 | F7: x
A8: gcad | B8: irq | C8: Ally | D8: 1 | E8: 0 | F8: x
A9: gcad | B9: sdf | C9: Ally | D9: 1 | E9: 0 | F9: x
A10: gcad | B10: isis | C10: Enemy | D10: 0 | E10: 1 | F10: x
A11: gcad | B11: mfs | C11: Enemy | D11: 0 | E11: 1 | F11: x
A12: hts | B12: rus | C12: Enemy | D12: 0 | E12: 1 | F12: 2017
A13: hts | B13: tur | C13: Enemy | D13: 0 | E13: 1 | F13: 2017
A14: hxp | B14: sdf | C14: Ally | D14: 1 | E14: 0 | F14: x
A15: hxp | B15: tur | C15: Enemy | D15: 0 | E15: 1 | F15: x
A16: hxp | B16: mfs | C16: Enemy | D16: 0 | E16: 1 | F16: x
A17: hxp | B17: opp | C17: Enemy | D17: 0 | E17: 1 | F17: x
A18: jaa | B18: aas | C18: Ally | D18: 1 | E18: 0 | F18: x
A19: jaa | B19: mfs | C19: Enemy | D19: 0 | E19: 1 | F19: x
A20: lf | B20: mfs | C20: Ally | D20: 1 | E20: 0 | F20: x
A21: lf | B21: ira | C21: Ally | D21: 1 | E21: 0 | F21: x
A22: lf | B22: hez | C22: Ally | D22: 1 | E22: 0 | F22: x
A23: lf | B23: isis | C23: Enemy | D23: 0 | E23: 1 | F23: x
A24: sl | B24: mfs | C24: Enemy | D24: 0 | E24: 1 | F24: 2014
A25: smm | B25: mfs | C25: Ally | D25: 1 | E25: 0 | F25: x
A26: smm | B26: opp | C26: Enemy | D26: 0 | E26: 1 | F26: x
A27: fsa | B27: tur | C27: Ally | D27: 1 | E27: 0 | F27: 2011
A28: fsa | B28: sdf | C28: Enemy | D28: 0 | E28: 1 | F28: 2011
A29: sf | B29: gcad | C29: Ally | D29: 1 | E29: 0 | F29: x
A30: sf | B30: usa | C30: Ally | D30: 1 | E30: 0 | F30: 2014 | G30: until 2018
A31: aas | B31: jaa | C31: Ally | D31: 1 | E31: 0 | F31: 2011
A32: aas | B32: fsa | C32: Ally | D32: 1 | E32: 0 | F32: 2011
A33: aas | B33: tur | C33: Ally | D33: 1 | E33: 0 | F33: 2011
A34: aas | B34: qat | C34: Ally | D34: 1 | E34: 0 | F34: 2011
A35: aas | B35: rus | C35: Enemy | D35: 0 | E35: 1 | F35: 2011
A36: sdf | B36: usa | C36: Ally | D36: 1 | E36: 0 | F36: 2015
A37: sdf | B37: gcad | C37: Ally | D37: 1 | E37: 0 | F37: x
A38: sdf | B38: hxp | C38: Ally | D38: 1 | E38: 0 | F38: x
A39: sdf | B39: mfs | C39: Enemy | D39: 0 | E39: 1 | F39: 2015
A40: sdf | B40: isis | C40: Enemy | D40: 0 | E40: 1 | F40: 2015
...
