Workbook

Sheet MAIN
A1: name | B1: min | C1: max | D1: Ethnicity
A2: Ahrar al-Sham | B2: 2013 | C2: 2018 | D2: =_xlfn.XLOOKUP(A2,Sheet2!A:A,Sheet2!C:C,0,0) -> Sunni
A3: Aknaf Bait al-Maqdis | B3: 2015 | C3: 2018 | D3: Sunni
A4: Al Qaeda | B4: 2014 | C4: 2023 | D4: =_xlfn.XLOOKUP(A4,Sheet2!A:A,Sheet2!C:C,0,0) -> Sunni
A5: Authenticity and Development Front | B5: 2014 | C5: 2016 | D5: Sunni
A6: Civilians | B6: 2004 | C6: 2023 | D6: Unknown-Mixed
A7: Faylaq al-Rahman | B7: 2015 | C7: 2018 | D7: =_xlfn.XLOOKUP(A7,Sheet2!A:A,Sheet2!C:C,0,0) -> Sunni
A8: Free Syrian Army | B8: 2012 | C8: 2023 | D8: =_xlfn.XLOOKUP(A8,Sheet2!A:A,Sheet2!C:C,0,0) -> Sunni
A9: HTS: Hayat Tahrir al-Sham | B9: 2012 | C9: 2024 | D9: =_xlfn.XLOOKUP(A9,Sheet2!A:A,Sheet2!C:C,0,0) -> Sunni
A10: Harakat Nour al-Din al-Zenki | B10: 2014 | C10: 2018 | D10: Sunni
A11: Hezbollah | B11: 2008 | C11: 2024 | D11: =_xlfn.XLOOKUP(A11,Sheet2!A:A,Sheet2!C:C,0,0) -> Shia
A12: Iran | B12: 2017 | C12: 2024 | D12: =_xlfn.XLOOKUP(A12,Sheet2!A:A,Sheet2!C:C,0,0) -> Shia
A13: Iraq | B13: 2013 | C13: 2020 | D13: Shia
A14: Israel | B14: 2004 | C14: 2024 | D14: Jewish
A15: JTS: Syria Liberation Front | B15: 2018 | C15: 2018 | D15: Sunni
A16: Jaish al-Muhajireen wal-Ansar | B16: 2014 | C16: 2014 | D16: Sunni
A17: Jaysh al-Fatah | B17: 2015 | C17: 2016 | D17: =_xlfn.XLOOKUP(A17,Sheet2!A:A,Sheet2!C:C,0,0) -> Sunni
A18: Jaysh al-Islam | B18: 2013 | C18: 2018 | D18: =_xlfn.XLOOKUP(A18,Sheet2!A:A,Sheet2!C:C,0,0) -> Sunni
A19: Jaysh al-Sanadeed | B19: 2014 | C19: 2015 | D19: Tribal
A20: Kurdish Front | B20: 2013 | C20: 2014 | D20: Kurdish
A21: Kurdish Islamic Front | B21: 2013 | C21: 2013 | D21: Kurdish
A22: Liwa al-Fateh | B22: 2013 | C22: 2013 | D22: Sunni
A23: Liwa al-Tawhid | B23: 2013 | C23: 2014 | D23: Sunni
A24: Military Forces of Syria | B24: 2004 | C24: 2024 | D24: =_xlfn.XLOOKUP(A24,Sheet2!A:A,Sheet2!C:C,0,0) -> Shia
A25: Mujahideen Army | B25: 2014 | C25: 2014 | D25: Sunni
A26: Mujahideen Shura Council | B26: 2014 | C26: 2014 | D26: Sunni
A27: Peoples Protection Units | B27: 2011 | C27: 2022 | D27: Kurdish
A28: Popular Mobilization Forces | B28: 2017 | C28: 2022 | D28: Shia
A29: Russia | B29: 2015 | C29: 2024 | D29: =_xlfn.XLOOKUP(A29,Sheet2!A:A,Sheet2!C:C,0,0) -> Secular
A30: Sham Legion | B30: 2014 | C30: 2018 | D30: =_xlfn.XLOOKUP(A30,Sheet2!A:A,Sheet2!C:C,0,0) -> Sunni
A31: Suqour al-Sham | B31: 2018 | C31: 2018 | D31: Sunni
A32: Syrian Democratic Forces | B32: 2014 | C32: 2024 | D32: =_xlfn.XLOOKUP(A32,Sheet2!A:A,Sheet2!C:C,0,0) -> Kurdish
A33: Syrian Insurgents | B33: 2011 | C33: 2023 | D33: Unknown-Mixed
A34: The Islamic State | B34: 2013 | C34: 2024 | D34: Sunni
A35: The Levantine Front | B35: 2014 | C35: 2018 | D35: =_xlfn.XLOOKUP(A35,Sheet2!A:A,Sheet2!C:C,0,0) -> Sunni
A36: The Southern Front | B36: 2013 | C36: 2018 | D36: =_xlfn.XLOOKUP(A36,Sheet2!A:A,Sheet2!C:C,0,0) -> Secular
A37: Turkey | B37: 2015 | C37: 2023 | D37: =_xlfn.XLOOKUP(A37,Sheet2!A:A,Sheet2!C:C,0,0) -> Sunni
A38: UK | B38: 2017 | C38: 2018 | D38: Secular
A39: USA | B39: 2014 | C39: 2024 | D39: =_xlfn.XLOOKUP(A39,Sheet2!A:A,Sheet2!C:C,0,0) -> Secular
A40: pre-HTS | B40: 2011 | C40: 2017 | D40: Sunni
...

Sheet Sheet2
A1: name | B1: Big | C1: Ethnic
A2: Al-Tawhid Army | B2: 1 | C2: Sunni
A3: Fawj Maghawir al Badiya | B3: 0 | C3: Unknown-Mixed
A4: Faylaq al-Rahman | B4: 1 | C4: Sunni
A5: Free Syrian Police | B5: 0 | C5: Unknown-Mixed
A6: Ghuraba Al-Janob | B6: 0 | C6: Unknown-Mixed
A7: Global Coalition Against Daesh | B7: 1 | C7: Secular
A8: HTS: Hayat Tahrir al-Sham | B8: 1 | C8: Sunni
A9: Harakat Hezbollah al Nujaba | B9: 0 | C9: Shia
A10: Islamist Militia | B10: 1 | C10: Unknown-Mixed
A11: Jaysh al-Ahrar | B11: 0 | C11: Sunni
A12: Liwa al-Haqq (Dar'a) | B12: 0 | C12: Sunni
A13: Military Forces of Iraq | B13: 1 | C13: Shia
... A35: USA | B35: 1 | C35: Secular

Sheet Sheet3
A1: name | B1: min | C1: max | D1: Ethnicity - OLD
A2: Ahrar al-Sham | B2: 2013 | C2: 2018 | D2: =_xlfn.XLOOKUP(A2,Sheet2!A:A,Sheet2!C:C,0,0) -> Sunni
A3: Aknaf Bait al-Maqdis | B3: 2015 | C3: 2018 | D3: =_xlfn.XLOOKUP(A3,Sheet2!A:A,Sheet2!C:C,0,0) -> 0 | E3: Sunni
A4: Al Qaeda | B4: 2014 | C4: 2023 | D4: =_xlfn.XLOOKUP(A4,Sheet2!A:A,Sheet2!C:C,0,0) -> Sunni
A5: Authenticity and Development Front | B5: 2014 | C5: 2016 | D5: =_xlfn.XLOOKUP(A5,Sheet2!A:A,Sheet2!C:C,0,0) -> 0 | E5: Sunni
A6: Civilians | B6: 2004 | C6: 2023 | D6: =_xlfn.XLOOKUP(A6,Sheet2!A:A,Sheet2!C:C,0,0) -> 0 | E6: Unknown-Mixed
A7: Faylaq al-Rahman | B7: 2015 | C7: 2018 | D7: =_xlfn.XLOOKUP(A7,Sheet2!A:A,Sheet2!C:C,0,0) -> Sunni
A8: Free Syrian Army | B8: 2012 | C8: 2023 | D8: =_xlfn.XLOOKUP(A8,Sheet2!A:A,Sheet2!C:C,0,0) -> Sunni
A9: HTS: Hayat Tahrir al-Sham | B9: 2012 | C9: 2024 | D9: =_xlfn.XLOOKUP(A9,Sheet2!A:A,Sheet2!C:C,0,0) -> Sunni
A10: Harakat Nour al-Din al-Zenki | B10: 2014 | C10: 2018 | D10: =_xlfn.XLOOKUP(A10,Sheet2!A:A,Sheet2!C:C,0,0) -> 0 | E10: Sunni
A11: Hezbollah | B11: 2008 | C11: 2024 | D11: =_xlfn.XLOOKUP(A11,Sheet2!A:A,Sheet2!C:C,0,0) -> Shia
A12: Iran | B12: 2017 | C12: 2024 | D12: =_xlfn.XLOOKUP(A12,Sheet2!A:A,Sheet2!C:C,0,0) -> Shia
A13: Iraq | B13: 2013 | C13: 2020 | D13: =_xlfn.XLOOKUP(A13,Sheet2!A:A,Sheet2!C:C,0,0) -> 0 | F13: x
A14: Israel | B14: 2004 | C14: 2024 | D14: =_xlfn.XLOOKUP(A14,Sheet2!A:A,Sheet2!C:C,0,0) -> 0 | F14: x
A15: JTS: Syria Liberation Front | B15: 2018 | C15: 2018 | D15: =_xlfn.XLOOKUP(A15,Sheet2!A:A,Sheet2!C:C,0,0) -> 0 | E15: Sunni
A16: Jaish al-Muhajireen wal-Ansar | B16: 2014 | C16: 2014 | D16: =_xlfn.XLOOKUP(A16,Sheet2!A:A,Sheet2!C:C,0,0) -> 0 | E16: Sunni
A17: Jaysh al-Fatah | B17: 2015 | C17: 2016 | D17: =_xlfn.XLOOKUP(A17,Sheet2!A:A,Sheet2!C:C,0,0) -> Sunni
A18: Jaysh al-Islam | B18: 2013 | C18: 2018 | D18: =_xlfn.XLOOKUP(A18,Sheet2!A:A,Sheet2!C:C,0,0) -> Sunni
A19: Jaysh al-Sanadeed | B19: 2014 | C19: 2015 | D19: =_xlfn.XLOOKUP(A19,Sheet2!A:A,Sheet2!C:C,0,0) -> 0 | E19: Tribal?
A20: Kurdish Front | B20: 2013 | C20: 2014 | D20: =_xlfn.XLOOKUP(A20,Sheet2!A:A,Sheet2!C:C,0,0) -> 0 | E20: Kurdish
A21: Kurdish Islamic Front | B21: 2013 | C21: 2013 | D21: =_xlfn.XLOOKUP(A21,Sheet2!A:A,Sheet2!C:C,0,0) -> 0 | E21: Kurdish
A22: Liwa al-Fateh | B22: 2013 | C22: 2013 | D22: =_xlfn.XLOOKUP(A22,Sheet2!A:A,Sheet2!C:C,0,0) -> 0 | E22: Sunni
A23: Liwa al-Tawhid | B23: 2013 | C23: 2014 | D23: Sunni
A24: Military Forces of Syria | B24: 2004 | C24: 2024 | D24: =_xlfn.XLOOKUP(A24,Sheet2!A:A,Sheet2!C:C,0,0) -> Shia
A25: Mujahideen Army | B25: 2014 | C25: 2014 | D25: =_xlfn.XLOOKUP(A25,Sheet2!A:A,Sheet2!C:C,0,0) -> 0 | E25: Sunni
A26: Mujahideen Shura Council | B26: 2014 | C26: 2014 | D26: =_xlfn.XLOOKUP(A26,Sheet2!A:A,Sheet2!C:C,0,0) -> 0 | E26: Sunni
A27: Peoples Protection Units | B27: 2011 | C27: 2022 | D27: =_xlfn.XLOOKUP(A27,Sheet2!A:A,Sheet2!C:C,0,0) -> 0 | F27: x
A28: Popular Mobilization Forces | B28: 2017 | C28: 2022 | D28: =_xlfn.XLOOKUP(A28,Sheet2!A:A,Sheet2!C:C,0,0) -> 0 | F28: x
A29: Russia | B29: 2015 | C29: 2024 | D29: =_xlfn.XLOOKUP(A29,Sheet2!A:A,Sheet2!C:C,0,0) -> Secular
A30: Sham Legion | B30: 2014 | C30: 2018 | D30: =_xlfn.XLOOKUP(A30,Sheet2!A:A,Sheet2!C:C,0,0) -> Sunni
A31: Suqour al-Sham | B31: 2018 | C31: 2018 | D31: =_xlfn.XLOOKUP(A31,Sheet2!A:A,Sheet2!C:C,0,0) -> 0 | E31: Sunni
A32: Syrian Democratic Forces | B32: 2014 | C32: 2024 | D32: =_xlfn.XLOOKUP(A32,Sheet2!A:A,Sheet2!C:C,0,0) -> Kurdish
A33: Syrian Insurgents | B33: 2011 | C33: 2023 | D33: =_xlfn.XLOOKUP(A33,Sheet2!A:A,Sheet2!C:C,0,0) -> 0 | E33: Unknown-Mixed
A34: The Islamic State | B34: 2013 | C34: 2024 | D34: Sunni
A35: The Levantine Front | B35: 2014 | C35: 2018 | D35: =_xlfn.XLOOKUP(A35,Sheet2!A:A,Sheet2!C:C,0,0) -> Sunni
A36: The Southern Front | B36: 2013 | C36: 2018 | D36: =_xlfn.XLOOKUP(A36,Sheet2!A:A,Sheet2!C:C,0,0) -> Secular
A37: Turkey | B37: 2015 | C37: 2023 | D37: =_xlfn.XLOOKUP(A37,Sheet2!A:A,Sheet2!C:C,0,0) -> Sunni
A38: UK | B38: 2017 | C38: 2018 | D38: =_xlfn.XLOOKUP(A38,Sheet2!A:A,Sheet2!C:C,0,0) -> 0 | E38: Secular | F38: x
A39: USA | B39: 2014 | C39: 2024 | D39: =_xlfn.XLOOKUP(A39,Sheet2!A:A,Sheet2!C:C,0,0) -> Secular
A40: x | B40: 2004 | C40: 2024 | D40: =_xlfn.XLOOKUP(A40,Sheet2!A:A,Sheet2!C:C,0,0) -> 0 | E40: Unknown-Mixed
