Workbook

Sheet Colouring
C3: dropping
C4: renaming
C5: external source needed
C6: new group
C7: keeping/ merging
C8: keeping/ merging, but less sure

Sheet MAIN_merging
A1: Name | B1: Total_fights | C1: Active years | D1: Min_year | E1: Max_year | F1: Action | G1: Umbrella | H1: Reasoning | I1: Column1 | J1: Column2
A2: 16th Division | B2: =_xlfn.XLOOKUP(A2,original_data!B:B,original_data!C:C,0,) -> 1 | C2: =_xlfn.XLOOKUP($A2,original_data!$B:$B,original_data!D:D,"x",0) -> 1 | D2: =_xlfn.XLOOKUP($A2,original_data!$B:$B,original_data!E:E,"x",0) -> 2014 | E2: =_xlfn.XLOOKUP($A2,original_data!$B:$B,original_data!F:F,"x",0) -> 2014 | F2: merge | G2: Free Syrian Army | H2: faction based on exteranal sources | I2: https://en.wikipedia.org/wiki/23rd_Division_(Syrian_rebel_group)
A3: Forces of the Caucasus Emirate | B3: =_xlfn.XLOOKUP(A3,original_data!B:B,original_data!C:C,0,) -> 1 | C3: =_xlfn.XLOOKUP($A3,original_data!$B:$B,original_data!D:D,"x",0) -> 1 | D3: =_xlfn.XLOOKUP($A3,original_data!$B:$B,original_data!E:E,"x",0) -> 2015 | E3: =_xlfn.XLOOKUP($A3,original_data!$B:$B,original_data!F:F,"x",0) -> 2015 | F3: drop | G3: x | H3: too small | I3: https://en.wikipedia.org/wiki/Caucasus_Emirate
A4: Government of Jordan | B4: =_xlfn.XLOOKUP(A4,original_data!B:B,original_data!C:C,0,) -> 1 | C4: =_xlfn.XLOOKUP($A4,original_data!$B:$B,original_data!D:D,"x",0) -> 1 | D4: =_xlfn.XLOOKUP($A4,original_data!$B:$B,original_data!E:E,"x",0) -> 2016 | E4: =_xlfn.XLOOKUP($A4,original_data!$B:$B,original_data!F:F,"x",0) -> 2016 | F4: drop | G4: x | H4: too small
A5: Government of Russia (Soviet Union) | B5: =_xlfn.XLOOKUP(A5,original_data!B:B,original_data!C:C,0,) -> 1 | C5: =_xlfn.XLOOKUP($A5,original_data!$B:$B,original_data!D:D,"x",0) -> 1 | D5: =_xlfn.XLOOKUP($A5,original_data!$B:$B,original_data!E:E,"x",0) -> 2015 | E5: =_xlfn.XLOOKUP($A5,original_data!$B:$B,original_data!F:F,"x",0) -> 2015 | F5: external | G5: Russia | H5: too small
A6: Opponents of al-Assad | B6: =_xlfn.XLOOKUP(A6,original_data!B:B,original_data!C:C,0,) -> 1 | C6: =_xlfn.XLOOKUP($A6,original_data!$B:$B,original_data!D:D,"x",0) -> 1 | D6: =_xlfn.XLOOKUP($A6,original_data!$B:$B,original_data!E:E,"x",0) -> 2011 | E6: =_xlfn.XLOOKUP($A6,original_data!$B:$B,original_data!F:F,"x",0) -> 2011 | F6: drop | G6: x | H6: too small
A7: Supporters of al-Assad | B7: =_xlfn.XLOOKUP(A7,original_data!B:B,original_data!C:C,0,) -> 1 | C7: =_xlfn.XLOOKUP($A7,original_data!$B:$B,original_data!D:D,"x",0) -> 1 | D7: =_xlfn.XLOOKUP($A7,original_data!$B:$B,original_data!E:E,"x",0) -> 2011 | E7: =_xlfn.XLOOKUP($A7,original_data!$B:$B,original_data!F:F,"x",0) -> 2011 | F7: drop | G7: x | H7: too small
A8: Tajamu Shuhada al-Sharqiya | B8: =_xlfn.XLOOKUP(A8,original_data!B:B,original_data!C:C,0,) -> 1 | C8: =_xlfn.XLOOKUP($A8,original_data!$B:$B,original_data!D:D,"x",0) -> 1 | D8: =_xlfn.XLOOKUP($A8,original_data!$B:$B,original_data!E:E,"x",0) -> 2018 | E8: =_xlfn.XLOOKUP($A8,original_data!$B:$B,original_data!F:F,"x",0) -> 2018 | F8: drop | G8: x | H8: too little information
A9: Omar al-Mukhtar Battalion | B9: =_xlfn.XLOOKUP(A9,original_data!B:B,original_data!C:C,0,) -> 2 | C9: =_xlfn.XLOOKUP($A9,original_data!$B:$B,original_data!D:D,"x",0) -> 1 | D9: =_xlfn.XLOOKUP($A9,original_data!$B:$B,original_data!E:E,"x",0) -> 2014 | E9: =_xlfn.XLOOKUP($A9,original_data!$B:$B,original_data!F:F,"x",0) -> 2014 | F9: merge | G9: Free Syrian Army | H9: faction based on exteranal sources | I9: They suggested that Moflihi had joined the Omar al-Mukhtar Battalion, one of the literally hundreds of rebel groups that have ties to the Free Syrian Army. | J9: https://www.npr.org/sections/parallels/2014/08/28/343805340/brooklyn-man-fights-in-syria-officials-unsure-of-the-threat
A10: PIJ | B10: =_xlfn.XLOOKUP(A10,original_data!B:B,original_data!C:C,0,) -> 2 | C10: =_xlfn.XLOOKUP($A10,original_data!$B:$B,original_data!D:D,"x",0) -> 2 | D10: =_xlfn.XLOOKUP($A10,original_data!$B:$B,original_data!E:E,"x",0) -> 2019 | E10: =_xlfn.XLOOKUP($A10,original_data!$B:$B,original_data!F:F,"x",0) -> 2020 | F10: drop | G10: x | H10: independent; operates mainly in Turkye
A11: PKK | B11: =_xlfn.XLOOKUP(A11,original_data!B:B,original_data!C:C,0,) -> 2 | C11: =_xlfn.XLOOKUP($A11,original_data!$B:$B,original_data!D:D,"x",0) -> 2 | D11: =_xlfn.XLOOKUP($A11,original_data!$B:$B,original_data!E:E,"x",0) -> 2017 | E11: =_xlfn.XLOOKUP($A11,original_data!$B:$B,original_data!F:F,"x",0) -> 2021 | F11: drop | G11: x | H11: independent; operates mainly in Isreal
A12: fdd | B12: =_xlfn.XLOOKUP(A12,original_data!B:B,original_data!C:C,0,) -> 0 | C12: =_xlfn.XLOOKUP($A12,original_data!$B:$B,original_data!D:D,"x",0) -> x | D12: =_xlfn.XLOOKUP($A12,original_data!$B:$B,original_data!E:E,"x",0) -> x | E12: =_xlfn.XLOOKUP($A12,original_data!$B:$B,original_data!F:F,"x",0) -> x | F12: merge | G12: Free Syrian Army | H12: faction based on exteranal sources | I12: https://www.counterextremism.com/armed-opposition-groups-nw-syria/ahrar-al-sharqiyah
A13: Hamza Asadullah Brigade | B13: =_xlfn.XLOOKUP(A13,original_data!B:B,original_data!C:C,0,) -> 4 | C13: =_xlfn.XLOOKUP($A13,original_data!$B:$B,original_data!D:D,"x",0) -> 1 | D13: =_xlfn.XLOOKUP($A13,original_data!$B:$B,original_data!E:E,"x",0) -> 2013 | E13: =_xlfn.XLOOKUP($A13,original_data!$B:$B,original_data!F:F,"x",0) -> 2013 | F13: drop | G13: x | H13: too small | I13: no
A14: al-Moutasem Brigade | B14: =_xlfn.XLOOKUP(A14,original_data!B:B,original_data!C:C,0,) -> 4 | C14: =_xlfn.XLOOKUP($A14,original_data!$B:$B,original_data!D:D,"x",0) -> 1 | D14: =_xlfn.XLOOKUP($A14,original_data!$B:$B,original_data!E:E,"x",0) -> 2020 | E14: =_xlfn.XLOOKUP($A14,original_data!$B:$B,original_data!F:F,"x",0) -> 2020 | F14: merge | G14: Free Syrian Army | H14: faction based on exteranal sources | I14: https://en.wikipedia.org/wiki/Mu%27tasim_Division
A15: Jaysh al-Asha’er | B15: =_xlfn.XLOOKUP(A15,original_data!B:B,original_data!C:C,0,) -> 5 | C15: =_xlfn.XLOOKUP($A15,original_data!$B:$B,original_data!D:D,"x",0) -> 1 | D15: =_xlfn.XLOOKUP($A15,original_data!$B:$B,original_data!E:E,"x",0) -> 2017 | E15: =_xlfn.XLOOKUP($A15,original_data!$B:$B,original_data!F:F,"x",0) -> 2017 | F15: merge | G15: Free Syrian Army | H15: faction based on exteranal sources | I15: https://en.wikipedia.org/wiki/Army_of_Free_Tribes
A16: Salahadin Brigade | B16: =_xlfn.XLOOKUP(A16,original_data!B:B,original_data!C:C,0,) -> 5 | C16: =_xlfn.XLOOKUP($A16,original_data!$B:$B,original_data!D:D,"x",0) -> 1 | D16: =_xlfn.XLOOKUP($A16,original_data!$B:$B,original_data!E:E,"x",0) -> 2012 | E16: =_xlfn.XLOOKUP($A16,original_data!$B:$B,original_data!F:F,"x",0) -> 2012 | F16: merge | G16: Free Syrian Army | H16: faction based on exteranal sources | I16: https://en.wikipedia.org/wiki/Saladin_Ayubi_Brigade
A17: Hamza Division | B17: =_xlfn.XLOOKUP(A17,original_data!B:B,original_data!C:C,0,) -> 6 | C17: =_xlfn.XLOOKUP($A17,original_data!$B:$B,original_data!D:D,"x",0) -> 2 | D17: =_xlfn.XLOOKUP($A17,original_data!$B:$B,original_data!E:E,"x",0) -> 2017 | E17: =_xlfn.XLOOKUP($A17,original_data!$B:$B,original_data!F:F,"x",0) -> 2020 | F17: merge | G17: Free Syrian Army | H17: SNA Encyclopedia | I17: https://en.wikipedia.org/wiki/Hamza_Division_(Aleppo)
A18: Hezbollah | B18: =_xlfn.XLOOKUP(A18,original_data!B:B,original_data!C:C,0,) -> 7 | C18: =_xlfn.XLOOKUP($A18,original_data!$B:$B,original_data!D:D,"x",0) -> 5 | D18: =_xlfn.XLOOKUP($A18,original_data!$B:$B,original_data!E:E,"x",0) -> 2014 | E18: =_xlfn.XLOOKUP($A18,original_data!$B:$B,original_data!F:F,"x",0) -> 2020 | F18: external | G18: Hezbollah | H18: too small
A19: Tanzim Hurras ad-Din | B19: =_xlfn.XLOOKUP(A19,original_data!B:B,original_data!C:C,0,) -> 7 | C19: =_xlfn.XLOOKUP($A19,original_data!$B:$B,original_data!D:D,"x",0) -> 3 | D19: =_xlfn.XLOOKUP($A19,original_data!$B:$B,original_data!E:E,"x",0) -> 2018 | E19: =_xlfn.XLOOKUP($A19,original_data!$B:$B,original_data!F:F,"x",0) -> 2021 | F19: merge | G19: Al Qaeda | H19: faction based on exteranal sources | I19: https://en.wikipedia.org/wiki/Hurras_al-Din
A20: Furqan Brigades | B20: =_xlfn.XLOOKUP(A20,original_data!B:B,original_data!C:C,0,) -> 8 | C20: =_xlfn.XLOOKUP($A20,original_data!$B:$B,original_data!D:D,"x",0) -> 1 | D20: =_xlfn.XLOOKUP($A20,original_data!$B:$B,original_data!E:E,"x",0) -> 2015 | E20: =_xlfn.XLOOKUP($A20,original_data!$B:$B,original_data!F:F,"x",0) -> 2015 | F20: merge | G20: Free Syrian Army | H20: affiliated with Free Syrian War | I20: https://en.wikipedia.org/wiki/Free_Syrian_Army
A21: Jaysh al-Jihad (Saraya al- Jihad) | B21: =_xlfn.XLOOKUP(A21,original_data!B:B,original_data!C:C,0,) -> 8 | C21: =_xlfn.XLOOKUP($A21,original_data!$B:$B,original_data!D:D,"x",0) -> 1 | D21: =_xlfn.XLOOKUP($A21,original_data!$B:$B,original_data!E:E,"x",0) -> 2015 | E21: =_xlfn.XLOOKUP($A21,original_data!$B:$B,original_data!F:F,"x",0) -> 2015 | F21: merge | G21: The Islamic State | H21: allgedly affiliated | I21: https://military-history.fandom.com/wiki/Jaysh_al-Jihad
A22: Yarmouk Army | B22: =_xlfn.XLOOKUP(A22,original_data!B:B,original_data!C:C,0,) -> 8 | C22: =_xlfn.XLOOKUP($A22,original_data!$B:$B,original_data!D:D,"x",0) -> 1 | D22: =_xlfn.XLOOKUP($A22,original_data!$B:$B,original_data!E:E,"x",0) -> 2015 | E22: =_xlfn.XLOOKUP($A22,original_data!$B:$B,original_data!F:F,"x",0) -> 2015 | F22: merge | G22: The Southern Front | H22: faction based on exteranal sources | I22: https://en.wikipedia.org/wiki/Southern_Front_(Syrian_rebel_group)
A23: Ahrar Ghurayan | B23: =_xlfn.XLOOKUP(A23,original_data!B:B,original_data!C:C,0,) -> 9 | C23: =_xlfn.XLOOKUP($A23,original_data!$B:$B,original_data!D:D,"x",0) -> 1 | D23: =_xlfn.XLOOKUP($A23,original_data!$B:$B,original_data!E:E,"x",0) -> 2014 | E23: =_xlfn.XLOOKUP($A23,original_data!$B:$B,original_data!F:F,"x",0) -> 2014 | F23: drop | G23: x | H23: too small; not enough information to merge
A24: Eastern Ghouta Unified Military Command | B24: =_xlfn.XLOOKUP(A24,original_data!B:B,original_data!C:C,0,) -> 9 | C24: =_xlfn.XLOOKUP($A24,original_data!$B:$B,original_data!D:D,"x",0) -> 1 | D24: =_xlfn.XLOOKUP($A24,original_data!$B:$B,original_data!E:E,"x",0) -> 2015 | E24: =_xlfn.XLOOKUP($A24,original_data!$B:$B,original_data!F:F,"x",0) -> 2015 | F24: drop | G24: x | H24: too small
A25: NSA | B25: =_xlfn.XLOOKUP(A25,original_data!B:B,original_data!C:C,0,) -> 9 | C25: =_xlfn.XLOOKUP($A25,original_data!$B:$B,original_data!D:D,"x",0) -> 2 | D25: =_xlfn.XLOOKUP($A25,original_data!$B:$B,original_data!E:E,"x",0) -> 2016 | E25: =_xlfn.XLOOKUP($A25,original_data!$B:$B,original_data!F:F,"x",0) -> 2017 | F25: merge | G25: Free Syrian Army | H25: called Jaysh Suriyah al-Jadid; faction based on external sources | I25: https://en.wikipedia.org/wiki/Revolutionary_Commando_Army
A26: Government of United States of America | B26: =_xlfn.XLOOKUP(A26,original_data!B:B,original_data!C:C,0,) -> 17 | C26: =_xlfn.XLOOKUP($A26,original_data!$B:$B,original_data!D:D,"x",0) -> 3 | D26: =_xlfn.XLOOKUP($A26,original_data!$B:$B,original_data!E:E,"x",0) -> 2014 | E26: =_xlfn.XLOOKUP($A26,original_data!$B:$B,original_data!F:F,"x",0) -> 2017 | F26: external | G26: USA | H26: foreign country
A27: Jaysh al Fatah Idlib | B27: =_xlfn.XLOOKUP(A27,original_data!B:B,original_data!C:C,0,) -> 17 | C27: =_xlfn.XLOOKUP($A27,original_data!$B:$B,original_data!D:D,"x",0) -> 2 | D27: =_xlfn.XLOOKUP($A27,original_data!$B:$B,original_data!E:E,"x",0) -> 2015 | E27: =_xlfn.XLOOKUP($A27,original_data!$B:$B,original_data!F:F,"x",0) -> 2016 | F27: keep | G27: Jaysh al-Fatah
A28: al-Qaida | B28: =_xlfn.XLOOKUP(A28,original_data!B:B,original_data!C:C,0,) -> 17 | C28: =_xlfn.XLOOKUP($A28,original_data!$B:$B,original_data!D:D,"x",0) -> 3 | D28: =_xlfn.XLOOKUP($A28,original_data!$B:$B,original_data!E:E,"x",0) -> 2014 | E28: =_xlfn.XLOOKUP($A28,original_data!$B:$B,original_data!F:F,"x",0) -> 2017 | F28: keep | G28: Al Qaeda | H28: Stanford
A29: Tahrir al- Sham Army | B29: =_xlfn.XLOOKUP(A29,original_data!B:B,original_data!C:C,0,) -> 18 | C29: =_xlfn.XLOOKUP($A29,original_data!$B:$B,original_data!D:D,"x",0) -> 2 | D29: =_xlfn.XLOOKUP($A29,original_data!$B:$B,original_data!E:E,"x",0) -> 2015 | E29: =_xlfn.XLOOKUP($A29,original_data!$B:$B,original_data!F:F,"x",0) -> 2016 | F29: keep | G29: HTS: Hayat Tahrir al-Sham | H29: Stanford
A30: FSA | B30: =_xlfn.XLOOKUP(A30,original_data!B:B,original_data!C:C,0,) -> 19 | C30: =_xlfn.XLOOKUP($A30,original_data!$B:$B,original_data!D:D,"x",0) -> 1 | D30: =_xlfn.XLOOKUP($A30,original_data!$B:$B,original_data!E:E,"x",0) -> 2017 | E30: =_xlfn.XLOOKUP($A30,original_data!$B:$B,original_data!F:F,"x",0) -> 2017 | F30: keep | G30: Free Syrian Army | H30: Stanford
A31: Jazeera-Euphrates Liberation Front | B31: =_xlfn.XLOOKUP(A31,original_data!B:B,original_data!C:C,0,) -> 20 | C31: =_xlfn.XLOOKUP($A31,original_data!$B:$B,original_data!D:D,"x",0) -> 1 | D31: =_xlfn.XLOOKUP($A31,original_data!$B:$B,original_data!E:E,"x",0) -> 2013 | E31: =_xlfn.XLOOKUP($A31,original_data!$B:$B,original_data!F:F,"x",0) -> 2013 | F31: drop | G31: x | H31: too independent
A32: al-Farouq Brigades | B32: =_xlfn.XLOOKUP(A32,original_data!B:B,original_data!C:C,0,) -> 20 | C32: =_xlfn.XLOOKUP($A32,original_data!$B:$B,original_data!D:D,"x",0) -> 1 | D32: =_xlfn.XLOOKUP($A32,original_data!$B:$B,original_data!E:E,"x",0) -> 2013 | E32: =_xlfn.XLOOKUP($A32,original_data!$B:$B,original_data!F:F,"x",0) -> 2013 | F32: merge | G32: Free Syrian Army | H32: faction based on exteranal sources
A33: Deir ez Zor Military Council | B33: =_xlfn.XLOOKUP(A33,original_data!B:B,original_data!C:C,0,) -> 21 | C33: =_xlfn.XLOOKUP($A33,original_data!$B:$B,original_data!D:D,"x",0) -> 1 | D33: =_xlfn.XLOOKUP($A33,original_data!$B:$B,original_data!E:E,"x",0) -> 2023 | E33: =_xlfn.XLOOKUP($A33,original_data!$B:$B,original_data!F:F,"x",0) -> 2023 | F33: merge | G33: Syrian Democratic Forces | H33: faction based on exteranal sources | I33: https://en.wikipedia.org/wiki/Deir_ez-Zor_Military_Council
A34: Ghuraba al-Sham | B34: =_xlfn.XLOOKUP(A34,original_data!B:B,original_data!C:C,0,) -> 27 | C34: =_xlfn.XLOOKUP($A34,original_data!$B:$B,original_data!D:D,"x",0) -> 2 | D34: =_xlfn.XLOOKUP($A34,original_data!$B:$B,original_data!E:E,"x",0) -> 2012 | E34: =_xlfn.XLOOKUP($A34,original_data!$B:$B,original_data!F:F,"x",0) -> 2013 | F34: merge | G34: Free Syrian Army | H34: faction based on exteranal sources | I34: https://en.wikipedia.org/wiki/Jabhat_Ghuraba_al-Sham
A35: Liwa al-Jihad fi Sabeel Allah | B35: =_xlfn.XLOOKUP(A35,original_data!B:B,original_data!C:C,0,) -> 33 | C35: =_xlfn.XLOOKUP($A35,original_data!$B:$B,original_data!D:D,"x",0) -> 1 | D35: =_xlfn.XLOOKUP($A35,original_data!$B:$B,original_data!E:E,"x",0) -> 2014 | E35: =_xlfn.XLOOKUP($A35,original_data!$B:$B,original_data!F:F,"x",0) -> 2014 | F35: merge | G35: Syrian Democratic Forces | H35: faction based on exteranal sources | I35: https://en.wikipedia.org/wiki/Jaysh_al-Salam
A36: Harkat Hazm | B36: =_xlfn.XLOOKUP(A36,original_data!B:B,original_data!C:C,0,) -> 40 | C36: =_xlfn.XLOOKUP($A36,original_data!$B:$B,original_data!D:D,"x",0) -> 2 | D36: =_xlfn.XLOOKUP($A36,original_data!$B:$B,original_data!E:E,"x",0) -> 2014 | E36: =_xlfn.XLOOKUP($A36,original_data!$B:$B,original_data!F:F,"x",0) -> 2015 | F36: keep | G36: Free Syrian Army | H36: affiliated with Free Syrian War | I36: affiliated
A37: Liwa al-Aqsa | B37: =_xlfn.XLOOKUP(A37,original_data!B:B,original_data!C:C,0,) -> 40 | C37: =_xlfn.XLOOKUP($A37,original_data!$B:$B,original_data!D:D,"x",0) -> 3 | D37: =_xlfn.XLOOKUP($A37,original_data!$B:$B,original_data!E:E,"x",0) -> 2014 | E37: =_xlfn.XLOOKUP($A37,original_data!$B:$B,original_data!F:F,"x",0) -> 2017 | F37: merge | G37: Al Qaeda | H37: affiliated | I37: https://en.wikipedia.org/wiki/Jund_al-Aqsa
A38: Ahfad al Rasoul Brigade | B38: =_xlfn.XLOOKUP(A38,original_data!B:B,original_data!C:C,0,) -> 42 | C38: =_xlfn.XLOOKUP($A38,original_data!$B:$B,original_data!D:D,"x",0) -> 1 | D38: =_xlfn.XLOOKUP($A38,original_data!$B:$B,original_data!E:E,"x",0) -> 2013 | E38: =_xlfn.XLOOKUP($A38,original_data!$B:$B,original_data!F:F,"x",0) -> 2013 | F38: drop | G38: x | H38: too independent | I38: independent, supported by Qatar
A39: Northern Storm Brigade | B39: =_xlfn.XLOOKUP(A39,original_data!B:B,original_data!C:C,0,) -> 42 | C39: =_xlfn.XLOOKUP($A39,original_data!$B:$B,original_data!D:D,"x",0) -> 2 | D39: =_xlfn.XLOOKUP($A39,original_data!$B:$B,original_data!E:E,"x",0) -> 2013 | E39: =_xlfn.XLOOKUP($A39,original_data!$B:$B,original_data!F:F,"x",0) -> 2014 | F39: merge | G39: Free Syrian Army | H39: faction based on exteranal sources | I39: https://en.wikipedia.org/wiki/Northern_Storm_Brigade
A40: Sons of Yarmouk Movement | B40: =_xlfn.XLOOKUP(A40,original_data!B:B,original_data!C:C,0,) -> 43 | C40: =_xlfn.XLOOKUP($A40,original_data!$B:$B,original_data!D:D,"x",0) -> 2 | D40: =_xlfn.XLOOKUP($A40,original_data!$B:$B,original_data!E:E,"x",0) -> 2016 | E40: =_xlfn.XLOOKUP($A40,original_data!$B:$B,original_data!F:F,"x",0) -> 2017 | F40: drop | G40: x | H40: seems to be mainly Palestinian military group
...

Sheet original_data
A1: id | B1: name | C1: ACDevent | D1: active | E1: mintime | F1: maxtime
A2: 1 | B2: 16th Division | C2: 1 | D2: 1 | E2: 2014 | F2: 2014
A3: 2 | B3: 23rd Division | C3: 284 | D3: 1 | E3: 2018 | F3: 2018
A4: 3 | B4: Ahfad al Rasoul Brigade | C4: 42 | D4: 1 | E4: 2013 | F4: 2013
A5: 4 | B5: Ahrar Ghurayan | C5: 9 | D5: 1 | E5: 2014 | F5: 2014
A6: 5 | B6: Ahrar al-Sham | C6: 930 | D6: 5 | E6: 2013 | F6: 2018
A7: 6 | B7: Ahrar al-Sharqiya | C7: 4 | D7: 1 | E7: 2020 | F7: 2020
A8: 7 | B8: Aknaf Bait al-Maqdis | C8: 155 | D8: 4 | E8: 2015 | F8: 2018
A9: 8 | B9: Army of Ahl al-Sunni wal Jamaa | C9: 136 | D9: 1 | E9: 2014 | F9: 2014
A10: 9 | B10: Army of Maoata al-Islami | C10: 147 | D10: 1 | E10: 2014 | F10: 2014
A11: 10 | B11: Army of al-Ikhlas | C11: 136 | D11: 1 | E11: 2014 | F11: 2014
A12: 11 | B12: Authenticity and Development Front | C12: 345 | D12: 3 | E12: 2014 | F12: 2016
A13: 12 | B13: Bayareq al-Shaaitat | C13: 136 | D13: 1 | E13: 2014 | F13: 2014
... A97: 96 | B97: al-Tawhid Brigade | C97: 125 | D97: 1 | E97: 2013 | F97: 2013
